<?xml version="1.0" ?>
<!-- =================================================================================== -->
<!-- |    This document was autogenerated by xacro from robotlab.xacro                 | -->
<!-- |    EDITING THIS FILE BY HAND IS NOT RECOMMENDED                                 | -->
<!-- =================================================================================== -->
<!--Generates a urdf from the macro in gantry_macro.xacro -->
<robot name="robotlab" xmlns:xacro="http://wiki.ros.org/xacro">
  <!-- created with Phobos 0.7 -->
  <link name="gantry_link_arm">
    <inertial>
      <origin rpy="0 0 0" xyz="0 0 0"/>
      <mass value="100.0"/>
      <inertia ixx="77.157539" ixy="-0.43952" ixz="-0.013708" iyy="77.235046" iyz="-8e-06" izz="1.060431"/>
    </inertial>
    <visual name="gantry_visual_arm">
      <origin rpy="1.57079632679 0 0" xyz="0 0 0"/>
      <geometry>
        <mesh filename="package://gantry_support/meshes/VIFS96.dae" scale="1.0 1.0 1.0"/>
      </geometry>
      <material name="gantry_VMtl98"/>
    </visual>
    <collision name="gantry_collision_arm">
      <origin rpy="0 0 0" xyz="0 0 1.34717"/>
      <geometry>
        <mesh filename="package://gantry_support/meshes/Cylinder.stl" scale="0.188288 0.188288 0.188288"/>
      </geometry>
    </collision>
  </link>
  <link name="gantry_link_base">
    <inertial>
      <origin rpy="0 0 0" xyz="0 0 0"/>
      <mass value="100.0"/>
      <inertia ixx="71.623734" ixy="3.1e-05" ixz="0" iyy="788.87262" iyz="1.2e-05" izz="851.100647"/>
    </inertial>
    <visual name="gantry_visual_base">
      <origin rpy="1.57079632679 -1.57079632679 0" xyz="0 0 0"/>
      <geometry>
        <mesh filename="package://gantry_support/meshes/VIFS01.001.dae" scale="1.0 1.0 1.0"/>
      </geometry>
      <material name="gantry_03___Default.001"/>
    </visual>
    <collision name="gantry_collision_base">
      <origin rpy="1.57079632679 -1.57079632679 0" xyz="0 0 0"/>
      <geometry>
        <mesh filename="package://gantry_support/meshes/VIFS01.000.stl" scale="1.0 1.0 1.0"/>
      </geometry>
    </collision>
  </link>
  <link name="gantry_link_leg">
    <inertial>
      <origin rpy="0 0 0" xyz="0 0.114805 -0.069116"/>
      <mass value="1000.0"/>
      <inertia ixx="1880.551147" ixy="0.000232" ixz="0" iyy="7958.77002" iyz="-13.379694" izz="6216.929688"/>
    </inertial>
    <visual name="gantry_visual_leg">
      <origin rpy="1.57079632679 -1.57079632679 0" xyz="0 0.114805 -0.069116"/>
      <geometry>
        <mesh filename="package://gantry_support/meshes/VIFS42.001.dae" scale="1.0 1.0 1.0"/>
      </geometry>
      <material name="gantry_01___Default.001"/>
    </visual>
    <collision name="gantry_collision_leg">
      <origin rpy="1.57079632679 -1.57079632679 0" xyz="0.000315 0.114805 -0.069116"/>
      <geometry>
        <mesh filename="package://gantry_support/meshes/VIFS42.000.stl" scale="1.0 1.0 1.0"/>
      </geometry>
    </collision>
  </link>
  <link name="gantry_link_trolley">
    <inertial>
      <origin rpy="0 0 0" xyz="0 0 0"/>
      <mass value="100.0"/>
      <inertia ixx="15.599652" ixy="1.71094" ixz="1.886528" iyy="9.19625" iyz="0.938975" izz="14.022485"/>
    </inertial>
    <visual name="gantry_visual_trolley">
      <origin rpy="-3.14159265359 0 0" xyz="0 0 0"/>
      <geometry>
        <mesh filename="package://gantry_support/meshes/VIFS43.001.dae" scale="1.0 1.0 1.0"/>
      </geometry>
      <material name="gantry_02___Default.001"/>
    </visual>
    <collision name="gantry_collision_trolley">
      <origin rpy="1.57079632679 0 0" xyz="-0.020567 0.254046 -0.042038"/>
      <geometry>
        <mesh filename="package://gantry_support/meshes/Cube.005.stl" scale="0.129538 0.485533 0.188935"/>
      </geometry>
    </collision>
  </link>
  <link name="gantry_robot_connection">
    </link>
  <link name="gantry_root">
    </link>
  <joint name="gantry_joint_e3" type="prismatic">
    <origin rpy="1.57079632679 0 0" xyz="-0.164527 -0.651668 -0.053205"/>
    <parent link="gantry_link_trolley"/>
    <child link="gantry_link_arm"/>
    <axis xyz="0 0 1.0"/>
    <limit effort="1.0" lower="-1.6" upper="0" velocity="0.55"/>
  </joint>
  <joint name="gantry_joint_base" type="fixed">
    <origin rpy="0 1.57079632679 0" xyz="0 0 0"/>
    <parent link="gantry_root"/>
    <child link="gantry_link_base"/>
  </joint>
  <joint name="gantry_joint_e1" type="prismatic">
    <origin rpy="0 0 0" xyz="-2.570369 -0.057403 0.844145"/>
    <parent link="gantry_link_base"/>
    <child link="gantry_link_leg"/>
    <axis xyz="0 0 -1.0"/>
    <limit effort="1.0" lower="0" upper="1.54" velocity="0.5"/>
  </joint>
  <joint name="gantry_joint_e2" type="prismatic">
    <origin rpy="-1.57079632679 -1.57079632679 0" xyz="-1.277963 2.407403 -0.476427"/>
    <parent link="gantry_link_leg"/>
    <child link="gantry_link_trolley"/>
    <axis xyz="0 0 -1.0"/>
    <limit effort="1.0" lower="0" upper="4.7" velocity="0.83"/>
  </joint>
  <joint name="gantry_robot_connection_joint" type="fixed">
    <origin rpy="-3.14159265359 0 0" xyz="-0.026405 0.000343 -1.392678"/>
    <parent link="gantry_link_arm"/>
    <child link="gantry_robot_connection"/>
  </joint>
  <material name="gantry_01___Default.001">
    <color rgba="0.1922 0.4588 1.0 1.0"/>
  </material>
  <material name="gantry_02___Default.001">
    <color rgba="1.0 1.0 1.0 1.0"/>
  </material>
  <material name="gantry_03___Default.001">
    <color rgba="0.5882 0.5882 0.5882 1.0"/>
  </material>
  <material name="gantry_VMtl98">
    <color rgba="0.5 0.5 0.5 1.0"/>
  </material>
  <!-- LINKS -->
  <!-- base link -->
  <link name="gantry_base_link">
    <inertial>
      <origin rpy="0 0 0" xyz="0 0 0"/>
      <mass value="2"/>
      <inertia ixx="0.01" ixy="0" ixz="0" iyy="0.01" iyz="0" izz="0.01"/>
    </inertial>
    <visual>
      <origin rpy="0 0 0" xyz="0 0 0"/>
      <geometry>
        <mesh filename="package://kuka_kr16_support/meshes/kr16_2/visual/base_link.dae"/>
      </geometry>
    </visual>
    <collision>
      <origin rpy="0 0 0" xyz="0 0 0"/>
      <geometry>
        <mesh filename="package://kuka_kr16_support/meshes/kr16_2/collision/base_link.stl"/>
      </geometry>
    </collision>
  </link>
  <!-- link 1 (A1) -->
  <link name="gantry_link_1">
    <inertial>
      <origin rpy="0 0 0" xyz="0 0 0"/>
      <mass value="2"/>
      <inertia ixx="0.01" ixy="0" ixz="0" iyy="0.01" iyz="0" izz="0.01"/>
    </inertial>
    <visual>
      <origin rpy="0 0 0" xyz="0 0 0"/>
      <geometry>
        <mesh filename="package://kuka_kr16_support/meshes/kr16_2/visual/link_1.dae"/>
      </geometry>
    </visual>
    <collision>
      <origin rpy="0 0 0" xyz="0 0 0"/>
      <geometry>
        <mesh filename="package://kuka_kr16_support/meshes/kr16_2/collision/link_1.stl"/>
      </geometry>
    </collision>
  </link>
  <!-- link 2 -->
  <link name="gantry_link_2">
    <inertial>
      <origin rpy="0 0 0" xyz="0 0 0"/>
      <mass value="2"/>
      <inertia ixx="0.01" ixy="0" ixz="0" iyy="0.01" iyz="0" izz="0.01"/>
    </inertial>
    <visual>
      <origin rpy="0 0 0" xyz="0 0 0"/>
      <geometry>
        <mesh filename="package://kuka_kr16_support/meshes/kr16_2/visual/link_2.dae"/>
      </geometry>
    </visual>
    <collision>
      <origin rpy="0 0 0" xyz="0 0 0"/>
      <geometry>
        <mesh filename="package://kuka_kr16_support/meshes/kr16_2/collision/link_2.stl"/>
      </geometry>
    </collision>
  </link>
  <!-- link 3 -->
  <link name="gantry_link_3">
    <inertial>
      <origin rpy="0 0 0" xyz="0 0 0"/>
      <mass value="2"/>
      <inertia ixx="0.01" ixy="0" ixz="0" iyy="0.01" iyz="0" izz="0.01"/>
    </inertial>
    <visual>
      <origin rpy="0 0 0" xyz="0 0 0"/>
      <geometry>
        <mesh filename="package://kuka_kr16_support/meshes/kr16_2/visual/link_3.dae"/>
      </geometry>
    </visual>
    <collision>
      <origin rpy="0 0 0" xyz="0 0 0"/>
      <geometry>
        <mesh filename="package://kuka_kr16_support/meshes/kr16_2/collision/link_3.stl"/>
      </geometry>
    </collision>
  </link>
  <!-- link 4 -->
  <link name="gantry_link_4">
    <inertial>
      <origin rpy="0 0 0" xyz="0 0 0"/>
      <mass value="2"/>
      <inertia ixx="0.01" ixy="0" ixz="0" iyy="0.01" iyz="0" izz="0.01"/>
    </inertial>
    <visual>
      <origin rpy="0 0 0" xyz="0 0 0"/>
      <geometry>
        <mesh filename="package://kuka_kr16_support/meshes/kr16_2/visual/link_4.dae"/>
      </geometry>
    </visual>
    <collision>
      <origin rpy="0 0 0" xyz="0 0 0"/>
      <geometry>
        <mesh filename="package://kuka_kr16_support/meshes/kr16_2/collision/link_4.stl"/>
      </geometry>
    </collision>
  </link>
  <!-- link 5 -->
  <link name="gantry_link_5">
    <inertial>
      <origin rpy="0 0 0" xyz="0 0 0"/>
      <mass value="2"/>
      <inertia ixx="0.01" ixy="0" ixz="0" iyy="0.01" iyz="0" izz="0.01"/>
    </inertial>
    <visual>
      <origin rpy="0 0 0" xyz="0 0 0"/>
      <geometry>
        <mesh filename="package://kuka_kr16_support/meshes/kr16_2/visual/link_5.dae"/>
      </geometry>
    </visual>
    <collision>
      <origin rpy="0 0 0" xyz="0 0 0"/>
      <geometry>
        <mesh filename="package://kuka_kr16_support/meshes/kr16_2/collision/link_5.stl"/>
      </geometry>
    </collision>
  </link>
  <!-- link 6 -->
  <link name="gantry_link_6">
    <inertial>
      <origin rpy="0 0 0" xyz="0 0 0"/>
      <mass value="2"/>
      <inertia ixx="0.01" ixy="0" ixz="0" iyy="0.01" iyz="0" izz="0.01"/>
    </inertial>
    <visual>
      <origin rpy="0 0 0" xyz="0 0 0"/>
      <geometry>
        <mesh filename="package://kuka_kr16_support/meshes/kr16_2/visual/link_6.dae"/>
      </geometry>
    </visual>
    <collision>
      <origin rpy="0 0 0" xyz="0 0 0"/>
      <geometry>
        <mesh filename="package://kuka_kr16_support/meshes/kr16_2/collision/link_6.stl"/>
      </geometry>
    </collision>
  </link>
  <!-- tool 0 -->
  <!-- This frame corresponds to the $FLANGE coordinate system in KUKA KRC controllers. -->
  <link name="gantry_tool0"/>
  <!-- END LINKS -->
  <!-- JOINTS -->
  <!-- joint 1 (A1) -->
  <joint name="gantry_joint_a1" type="revolute">
    <origin rpy="0 0 0" xyz="0 0 0.675"/>
    <parent link="gantry_base_link"/>
    <child link="gantry_link_1"/>
    <axis xyz="0 0 -1"/>
    <limit effort="0" lower="-3.22885911619" upper="3.22885911619" velocity="2.72271363311"/>
  </joint>
  <!-- joint 2 (A2) -->
  <joint name="gantry_joint_a2" type="revolute">
    <origin rpy="0 0 0" xyz="0.26 0 0"/>
    <parent link="gantry_link_1"/>
    <child link="gantry_link_2"/>
    <axis xyz="0 1 0"/>
    <limit effort="0" lower="-2.70526034059" upper="0.610865238198" velocity="2.72271363311"/>
  </joint>
  <!-- joint 3 (A3) -->
  <joint name="gantry_joint_a3" type="revolute">
    <origin rpy="0 0 0" xyz="0.68 0 0"/>
    <parent link="gantry_link_2"/>
    <child link="gantry_link_3"/>
    <axis xyz="0 1 0"/>
    <limit effort="0" lower="-2.26892802759" upper="2.68780704807" velocity="2.72271363311"/>
  </joint>
  <!-- joint 4 (A4) -->
  <joint name="gantry_joint_a4" type="revolute">
    <origin rpy="0 0 0" xyz="0.67 0 -0.035"/>
    <parent link="gantry_link_3"/>
    <child link="gantry_link_4"/>
    <axis xyz="-1 0 0"/>
    <limit effort="0" lower="-6.10865238198" upper="6.10865238198" velocity="5.75958653158"/>
  </joint>
  <!-- joint 5 (A5) -->
  <joint name="gantry_joint_a5" type="revolute">
    <origin rpy="0 0 0" xyz="0 0 0"/>
    <parent link="gantry_link_4"/>
    <child link="gantry_link_5"/>
    <axis xyz="0 1 0"/>
    <limit effort="0" lower="-2.26892802759" upper="2.26892802759" velocity="5.75958653158"/>
  </joint>
  <!-- joint 6 (A6) -->
  <joint name="gantry_joint_a6" type="revolute">
    <origin rpy="0 0 0" xyz="0 0 0"/>
    <parent link="gantry_link_5"/>
    <child link="gantry_link_6"/>
    <axis xyz="-1 0 0"/>
    <limit effort="0" lower="-6.10865238198" upper="6.10865238198" velocity="10.7337748998"/>
  </joint>
  <!-- tool frame - fixed frame -->
  <joint name="gantry_joint_a6-tool0" type="fixed">
    <parent link="gantry_link_6"/>
    <child link="gantry_tool0"/>
    <origin rpy="0 1.57079632679 0" xyz="0.158 0 0"/>
  </joint>
  <!-- END JOINTS -->
  <!-- ROS base_link to KUKA $ROBROOT coordinate system transform -->
  <link name="gantry_base"/>
  <joint name="gantry_base_link-base" type="fixed">
    <origin rpy="0 0 0" xyz="0 0 0"/>
    <parent link="gantry_base_link"/>
    <child link="gantry_base"/>
  </joint>
  <joint name="gantry_gantry_robot" type="fixed">
    <origin rpy="0 0 1.57079632679" xyz="0 0 0"/>
    <parent link="gantry_robot_connection"/>
    <child link="gantry_base_link"/>
  </joint>
  <!-- LINKS -->
  <!-- base link -->
  <link name="floor_base_link">
    <inertial>
      <origin rpy="0 0 0" xyz="0 0 0"/>
      <mass value="2"/>
      <inertia ixx="0.01" ixy="0" ixz="0" iyy="0.01" iyz="0" izz="0.01"/>
    </inertial>
    <visual>
      <origin rpy="0 0 0" xyz="0 0 0"/>
      <geometry>
        <mesh filename="package://kuka_kr16_support/meshes/kr16_2/visual/base_link.dae"/>
      </geometry>
    </visual>
    <collision>
      <origin rpy="0 0 0" xyz="0 0 0"/>
      <geometry>
        <mesh filename="package://kuka_kr16_support/meshes/kr16_2/collision/base_link.stl"/>
      </geometry>
    </collision>
  </link>
  <!-- link 1 (A1) -->
  <link name="floor_link_1">
    <inertial>
      <origin rpy="0 0 0" xyz="0 0 0"/>
      <mass value="2"/>
      <inertia ixx="0.01" ixy="0" ixz="0" iyy="0.01" iyz="0" izz="0.01"/>
    </inertial>
    <visual>
      <origin rpy="0 0 0" xyz="0 0 0"/>
      <geometry>
        <mesh filename="package://kuka_kr16_support/meshes/kr16_2/visual/link_1.dae"/>
      </geometry>
    </visual>
    <collision>
      <origin rpy="0 0 0" xyz="0 0 0"/>
      <geometry>
        <mesh filename="package://kuka_kr16_support/meshes/kr16_2/collision/link_1.stl"/>
      </geometry>
    </collision>
  </link>
  <!-- link 2 -->
  <link name="floor_link_2">
    <inertial>
      <origin rpy="0 0 0" xyz="0 0 0"/>
      <mass value="2"/>
      <inertia ixx="0.01" ixy="0" ixz="0" iyy="0.01" iyz="0" izz="0.01"/>
    </inertial>
    <visual>
      <origin rpy="0 0 0" xyz="0 0 0"/>
      <geometry>
        <mesh filename="package://kuka_kr16_support/meshes/kr16_2/visual/link_2.dae"/>
      </geometry>
    </visual>
    <collision>
      <origin rpy="0 0 0" xyz="0 0 0"/>
      <geometry>
        <mesh filename="package://kuka_kr16_support/meshes/kr16_2/collision/link_2.stl"/>
      </geometry>
    </collision>
  </link>
  <!-- link 3 -->
  <link name="floor_link_3">
    <inertial>
      <origin rpy="0 0 0" xyz="0 0 0"/>
      <mass value="2"/>
      <inertia ixx="0.01" ixy="0" ixz="0" iyy="0.01" iyz="0" izz="0.01"/>
    </inertial>
    <visual>
      <origin rpy="0 0 0" xyz="0 0 0"/>
      <geometry>
        <mesh filename="package://kuka_kr16_support/meshes/kr16_2/visual/link_3.dae"/>
      </geometry>
    </visual>
    <collision>
      <origin rpy="0 0 0" xyz="0 0 0"/>
      <geometry>
        <mesh filename="package://kuka_kr16_support/meshes/kr16_2/collision/link_3.stl"/>
      </geometry>
    </collision>
  </link>
  <!-- link 4 -->
  <link name="floor_link_4">
    <inertial>
      <origin rpy="0 0 0" xyz="0 0 0"/>
      <mass value="2"/>
      <inertia ixx="0.01" ixy="0" ixz="0" iyy="0.01" iyz="0" izz="0.01"/>
    </inertial>
    <visual>
      <origin rpy="0 0 0" xyz="0 0 0"/>
      <geometry>
        <mesh filename="package://kuka_kr16_support/meshes/kr16_2/visual/link_4.dae"/>
      </geometry>
    </visual>
    <collision>
      <origin rpy="0 0 0" xyz="0 0 0"/>
      <geometry>
        <mesh filename="package://kuka_kr16_support/meshes/kr16_2/collision/link_4.stl"/>
      </geometry>
    </collision>
  </link>
  <!-- link 5 -->
  <link name="floor_link_5">
    <inertial>
      <origin rpy="0 0 0" xyz="0 0 0"/>
      <mass value="2"/>
      <inertia ixx="0.01" ixy="0" ixz="0" iyy="0.01" iyz="0" izz="0.01"/>
    </inertial>
    <visual>
      <origin rpy="0 0 0" xyz="0 0 0"/>
      <geometry>
        <mesh filename="package://kuka_kr16_support/meshes/kr16_2/visual/link_5.dae"/>
      </geometry>
    </visual>
    <collision>
      <origin rpy="0 0 0" xyz="0 0 0"/>
      <geometry>
        <mesh filename="package://kuka_kr16_support/meshes/kr16_2/collision/link_5.stl"/>
      </geometry>
    </collision>
  </link>
  <!-- link 6 -->
  <link name="floor_link_6">
    <inertial>
      <origin rpy="0 0 0" xyz="0 0 0"/>
      <mass value="2"/>
      <inertia ixx="0.01" ixy="0" ixz="0" iyy="0.01" iyz="0" izz="0.01"/>
    </inertial>
    <visual>
      <origin rpy="0 0 0" xyz="0 0 0"/>
      <geometry>
        <mesh filename="package://kuka_kr16_support/meshes/kr16_2/visual/link_6.dae"/>
      </geometry>
    </visual>
    <collision>
      <origin rpy="0 0 0" xyz="0 0 0"/>
      <geometry>
        <mesh filename="package://kuka_kr16_support/meshes/kr16_2/collision/link_6.stl"/>
      </geometry>
    </collision>
  </link>
  <!-- tool 0 -->
  <!-- This frame corresponds to the $FLANGE coordinate system in KUKA KRC controllers. -->
  <link name="floor_tool0"/>
  <!-- END LINKS -->
  <!-- JOINTS -->
  <!-- joint 1 (A1) -->
  <joint name="floor_joint_a1" type="revolute">
    <origin rpy="0 0 0" xyz="0 0 0.675"/>
    <parent link="floor_base_link"/>
    <child link="floor_link_1"/>
    <axis xyz="0 0 -1"/>
    <limit effort="0" lower="-3.22885911619" upper="3.22885911619" velocity="2.72271363311"/>
  </joint>
  <!-- joint 2 (A2) -->
  <joint name="floor_joint_a2" type="revolute">
    <origin rpy="0 0 0" xyz="0.26 0 0"/>
    <parent link="floor_link_1"/>
    <child link="floor_link_2"/>
    <axis xyz="0 1 0"/>
    <limit effort="0" lower="-2.70526034059" upper="0.610865238198" velocity="2.72271363311"/>
  </joint>
  <!-- joint 3 (A3) -->
  <joint name="floor_joint_a3" type="revolute">
    <origin rpy="0 0 0" xyz="0.68 0 0"/>
    <parent link="floor_link_2"/>
    <child link="floor_link_3"/>
    <axis xyz="0 1 0"/>
    <limit effort="0" lower="-2.26892802759" upper="2.68780704807" velocity="2.72271363311"/>
  </joint>
  <!-- joint 4 (A4) -->
  <joint name="floor_joint_a4" type="revolute">
    <origin rpy="0 0 0" xyz="0.67 0 -0.035"/>
    <parent link="floor_link_3"/>
    <child link="floor_link_4"/>
    <axis xyz="-1 0 0"/>
    <limit effort="0" lower="-6.10865238198" upper="6.10865238198" velocity="5.75958653158"/>
  </joint>
  <!-- joint 5 (A5) -->
  <joint name="floor_joint_a5" type="revolute">
    <origin rpy="0 0 0" xyz="0 0 0"/>
    <parent link="floor_link_4"/>
    <child link="floor_link_5"/>
    <axis xyz="0 1 0"/>
    <limit effort="0" lower="-2.26892802759" upper="2.26892802759" velocity="5.75958653158"/>
  </joint>
  <!-- joint 6 (A6) -->
  <joint name="floor_joint_a6" type="revolute">
    <origin rpy="0 0 0" xyz="0 0 0"/>
    <parent link="floor_link_5"/>
    <child link="floor_link_6"/>
    <axis xyz="-1 0 0"/>
    <limit effort="0" lower="-6.10865238198" upper="6.10865238198" velocity="10.7337748998"/>
  </joint>
  <!-- tool frame - fixed frame -->
  <joint name="floor_joint_a6-tool0" type="fixed">
    <parent link="floor_link_6"/>
    <child link="floor_tool0"/>
    <origin rpy="0 1.57079632679 0" xyz="0.158 0 0"/>
  </joint>
  <!-- END JOINTS -->
  <!-- ROS base_link to KUKA $ROBROOT coordinate system transform -->
  <link name="floor_base"/>
  <joint name="floor_base_link-base" type="fixed">
    <origin rpy="0 0 0" xyz="0 0 0"/>
    <parent link="floor_base_link"/>
    <child link="floor_base"/>
  </joint>
  <link name="gantry_FTC-50-80">
    <visual>
      <geometry>
        <cylinder length="0.0485" radius="0.082"/>
      </geometry>
    </visual>
    <collision>
      <geometry>
        <cylinder length="0.05" radius="0.1"/>
      </geometry>
    </collision>
    <inertial>
      <!-- data from http://www.comoso.com/uploads/showcase/manuals/Schunk_Comoso_eng_robot_accessoires.pdf -->
      <mass value="1.56"/>
      <inertia ixx="0.00395" ixy="0.0" ixz="0.0" iyy="0.00395" iyz="0.0" izz="0.0058"/>
    </inertial>
  </link>
  <link name="floor_FTC-50-80">
    <visual>
      <geometry>
        <cylinder length="0.0485" radius="0.082"/>
      </geometry>
    </visual>
    <collision>
      <geometry>
        <cylinder length="0.05" radius="0.1"/>
      </geometry>
    </collision>
    <inertial>
      <!-- data from http://www.comoso.com/uploads/showcase/manuals/Schunk_Comoso_eng_robot_accessoires.pdf -->
      <mass value="1.56"/>
      <inertia ixx="0.00395" ixy="0.0" ixz="0.0" iyy="0.00395" iyz="0.0" izz="0.0058"/>
    </inertial>
  </link>
  <link name="gantry_SWK-020">
    <visual>
      <origin rpy="0 3.14159265359 0" xyz="0 0 0"/>
      <geometry>
        <mesh filename="package://robotlab_support/meshes/schunk/visual/SWK-020.dae" scale="0.001 0.001 0.001"/>
      </geometry>
    </visual>
    <collision>
      <origin rpy="1.57079632679 3.14159265359 0" xyz="0 0 0"/>
      <geometry>
        <mesh filename="package://robotlab_support/meshes/schunk/visual/SWK-020.stl" scale="0.002 0.002 0.002"/>
      </geometry>
    </collision>
    <inertial>
      <!-- data from http://www.comoso.com/uploads/showcase/manuals/Schunk_Comoso_eng_robot_accessoires.pdf -->
      <mass value="0.8"/>
      <inertia ixx="0.14555" ixy="0.0" ixz="0.0" iyy="0.14555" iyz="0.0" izz="0.29104"/>
    </inertial>
  </link>
  <link name="floor_SWK-020">
    <visual>
      <origin rpy="0 3.14159265359 0" xyz="0 0 0"/>
      <geometry>
        <mesh filename="package://robotlab_support/meshes/schunk/visual/SWK-020.dae" scale="0.001 0.001 0.001"/>
      </geometry>
    </visual>
    <collision>
      <origin rpy="1.57079632679 3.14159265359 0" xyz="0 0 0"/>
      <geometry>
        <mesh filename="package://robotlab_support/meshes/schunk/visual/SWK-020.stl" scale="0.002 0.002 0.002"/>
      </geometry>
    </collision>
    <inertial>
      <!-- data from http://www.comoso.com/uploads/showcase/manuals/Schunk_Comoso_eng_robot_accessoires.pdf -->
      <mass value="0.8"/>
      <inertia ixx="0.14555" ixy="0.0" ixz="0.0" iyy="0.14555" iyz="0.0" izz="0.29104"/>
    </inertial>
  </link>
  <link name="gantry_A1_utility_plate">
    <visual>
      <geometry>
        <box size="0.67 0.26 0.005"/>
      </geometry>
      <material name="black">
        <color rgba="0 0 0 1"/>
      </material>
    </visual>
    <collision>
      <geometry>
        <box size="0.7 0.3 0.10"/>
      </geometry>
    </collision>
    <inertial>
      <mass value="0.5"/>
      <inertia ixx="0.0028177" ixy="0" ixz="0" iyy="0.018705208" iyz="0" izz="0.0215208"/>
    </inertial>
  </link>
  <link name="gantry_A1_BOX">
    <visual>
      <geometry>
        <box size="0.167 0.107 0.065"/>
      </geometry>
      <material name="backish">
        <color rgba="0.15 0.15 0.15 1"/>
      </material>
      <origin rpy="0 0 0" xyz="-0.0835 -0.0535 -0.0325"/>
    </visual>
    <collision>
      <geometry>
        <box size="0.18 0.12 0.08"/>
      </geometry>
      <origin rpy="0 0 0" xyz="-0.0835 -0.0535 -0.0325"/>
    </collision>
    <inertial>
      <mass value="0.5"/>
      <inertia ixx="0.000866" ixy="0" ixz="0" iyy="0.001428708" iyz="0" izz="0.0016390833"/>
    </inertial>
  </link>
  <link name="gantry_A1_BOX2">
    <visual>
      <geometry>
        <box size="0.167 0.107 0.065"/>
      </geometry>
      <material name="blackish">
        <color rgba="0.15 0.15 0.15 1"/>
      </material>
      <origin rpy="0 0 0" xyz="-0.0835 -0.0535 0.0325"/>
    </visual>
    <collision>
      <geometry>
        <box size="0.18 0.12 0.08"/>
      </geometry>
      <origin rpy="0 0 0" xyz="-0.0835 -0.0535 -0.0325"/>
    </collision>
    <inertial>
      <mass value="0.5"/>
      <inertia ixx="0.000866" ixy="0" ixz="0" iyy="0.001428708" iyz="0" izz="0.0016390833"/>
    </inertial>
  </link>
  <link name="gantry_A1_DCDC">
    <visual>
      <geometry>
        <box size="0.17 0.26 0.1"/>
      </geometry>
      <material name="greyish">
        <color rgba="0.5 0.5 0.5 1"/>
      </material>
      <origin rpy="0 0 0" xyz="-0.085 -0.13 0.05"/>
    </visual>
    <collision>
      <geometry>
        <box size="0.2 0.3 0.15"/>
      </geometry>
      <origin rpy="0 0 0" xyz="-0.085 -0.13 0.05"/>
    </collision>
    <inertial>
      <mass value="0.5"/>
      <inertia ixx="0.000866" ixy="0" ixz="0" iyy="0.001428708" iyz="0" izz="0.0016390833"/>
    </inertial>
  </link>
  <joint name="gantry_A1_plate_DCDC" type="fixed">
    <parent link="gantry_A1_utility_plate"/>
    <child link="gantry_A1_DCDC"/>
    <origin rpy="0 0 0" xyz="0.335 0.13 0.0025"/>
  </joint>
  <joint name="gantry_A1_plate_BOX" type="fixed">
    <parent link="gantry_A1_utility_plate"/>
    <child link="gantry_A1_BOX"/>
    <origin rpy="0 0 0" xyz="-0.168 0.13 -0.0025 "/>
  </joint>
  <joint name="gantry_A1_plate_BOX2" type="fixed">
    <parent link="gantry_A1_utility_plate"/>
    <child link="gantry_A1_BOX2"/>
    <origin rpy="0 0 0" xyz="-0.168 0.13 0.0025 "/>
  </joint>
  <link name="floor_A1_utility_plate">
    <visual>
      <geometry>
        <box size="0.67 0.26 0.005"/>
      </geometry>
      <material name="black">
        <color rgba="0 0 0 1"/>
      </material>
    </visual>
    <collision>
      <geometry>
        <box size="0.7 0.3 0.10"/>
      </geometry>
    </collision>
    <inertial>
      <mass value="0.5"/>
      <inertia ixx="0.0028177" ixy="0" ixz="0" iyy="0.018705208" iyz="0" izz="0.0215208"/>
    </inertial>
  </link>
  <link name="floor_A1_BOX">
    <visual>
      <geometry>
        <box size="0.167 0.107 0.065"/>
      </geometry>
      <material name="backish">
        <color rgba="0.15 0.15 0.15 1"/>
      </material>
      <origin rpy="0 0 0" xyz="-0.0835 -0.0535 -0.0325"/>
    </visual>
    <collision>
      <geometry>
        <box size="0.18 0.12 0.08"/>
      </geometry>
      <origin rpy="0 0 0" xyz="-0.0835 -0.0535 -0.0325"/>
    </collision>
    <inertial>
      <mass value="0.5"/>
      <inertia ixx="0.000866" ixy="0" ixz="0" iyy="0.001428708" iyz="0" izz="0.0016390833"/>
    </inertial>
  </link>
  <link name="floor_A1_BOX2">
    <visual>
      <geometry>
        <box size="0.167 0.107 0.065"/>
      </geometry>
      <material name="blackish">
        <color rgba="0.15 0.15 0.15 1"/>
      </material>
      <origin rpy="0 0 0" xyz="-0.0835 -0.0535 0.0325"/>
    </visual>
    <collision>
      <geometry>
        <box size="0.18 0.12 0.08"/>
      </geometry>
      <origin rpy="0 0 0" xyz="-0.0835 -0.0535 -0.0325"/>
    </collision>
    <inertial>
      <mass value="0.5"/>
      <inertia ixx="0.000866" ixy="0" ixz="0" iyy="0.001428708" iyz="0" izz="0.0016390833"/>
    </inertial>
  </link>
  <link name="floor_A1_DCDC">
    <visual>
      <geometry>
        <box size="0.17 0.26 0.1"/>
      </geometry>
      <material name="greyish">
        <color rgba="0.5 0.5 0.5 1"/>
      </material>
      <origin rpy="0 0 0" xyz="-0.085 -0.13 0.05"/>
    </visual>
    <collision>
      <geometry>
        <box size="0.2 0.3 0.15"/>
      </geometry>
      <origin rpy="0 0 0" xyz="-0.085 -0.13 0.05"/>
    </collision>
    <inertial>
      <mass value="0.5"/>
      <inertia ixx="0.000866" ixy="0" ixz="0" iyy="0.001428708" iyz="0" izz="0.0016390833"/>
    </inertial>
  </link>
  <joint name="floor_A1_plate_DCDC" type="fixed">
    <parent link="floor_A1_utility_plate"/>
    <child link="floor_A1_DCDC"/>
    <origin rpy="0 0 0" xyz="0.335 0.13 0.0025"/>
  </joint>
  <joint name="floor_A1_plate_BOX" type="fixed">
    <parent link="floor_A1_utility_plate"/>
    <child link="floor_A1_BOX"/>
    <origin rpy="0 0 0" xyz="-0.168 0.13 -0.0025 "/>
  </joint>
  <joint name="floor_A1_plate_BOX2" type="fixed">
    <parent link="floor_A1_utility_plate"/>
    <child link="floor_A1_BOX2"/>
    <origin rpy="0 0 0" xyz="-0.168 0.13 0.0025 "/>
  </joint>
  <link name="floor_A3_box">
    <visual>
      <geometry>
        <box size="0.28 0.17 0.07"/>
      </geometry>
      <material name="ish">
        <color rgba="0.8 0.8 0.8 1"/>
      </material>
      <origin rpy="0 0 0" xyz="0 -0.085 -0.035"/>
    </visual>
    <collision>
      <geometry>
        <box size="0.35 0.25 0.1"/>
      </geometry>
      <origin rpy="0 0 0" xyz="0 -0.085 -0.035"/>
    </collision>
    <inertial>
      <mass value="0.5"/>
      <inertia ixx="0.001408" ixy="0" ixz="0" iyy="0.00347" iyz="0" izz="0.004470"/>
    </inertial>
  </link>
  <link name="gantry_A3_box">
    <visual>
      <geometry>
        <box size="0.28 0.17 0.07"/>
      </geometry>
      <material name="ish">
        <color rgba="0.8 0.8 0.8 1"/>
      </material>
      <origin rpy="0 0 0" xyz="0 -0.085 -0.035"/>
    </visual>
    <collision>
      <geometry>
        <box size="0.35 0.25 0.1"/>
      </geometry>
      <origin rpy="0 0 0" xyz="0 -0.085 -0.035"/>
    </collision>
    <inertial>
      <mass value="0.5"/>
      <inertia ixx="0.001408" ixy="0" ixz="0" iyy="0.00347" iyz="0" izz="0.004470"/>
    </inertial>
  </link>
  <link name="root">
    </link>
  <joint name="root_gantry" type="fixed">
    <origin rpy="0 0 0" xyz="0 0 0.0"/>
    <parent link="root"/>
    <child link="gantry_root"/>
  </joint>
  <joint name="root_floor" type="fixed">
    <origin rpy="0 0 -1.57079632679" xyz="-0.402 0.486 0"/>
    <parent link="root"/>
    <child link="floor_base_link"/>
  </joint>
  <joint name="gantry_tool0_ftc" type="fixed">
    <origin rpy="0 0 0" xyz="0 0 0"/>
    <parent link="gantry_tool0"/>
    <child link="gantry_FTC-50-80"/>
  </joint>
  <joint name="gantry_ftc_sws" type="fixed">
    <origin rpy="0 0 0" xyz="0 0 0.0485"/>
    <parent link="gantry_FTC-50-80"/>
    <child link="gantry_SWK-020"/>
  </joint>
  <joint name="floor_tool0_ftc" type="fixed">
    <origin rpy="0 0 0" xyz="0 0 0"/>
    <parent link="floor_tool0"/>
    <child link="floor_FTC-50-80"/>
  </joint>
  <joint name="floor_ftc_sws" type="fixed">
    <origin rpy="0 0 0" xyz="0 0 0.0485"/>
    <parent link="floor_FTC-50-80"/>
    <child link="floor_SWK-020"/>
  </joint>
  <joint name="gantry_A1_utility" type="fixed">
    <origin rpy="0 0 0" xyz="0.1 0.30 -0.25"/>
    <parent link="gantry_link_1"/>
    <child link="gantry_A1_utility_plate"/>
  </joint>
  <joint name="floor_A1_utility" type="fixed">
    <origin rpy="0 0 0" xyz="0.1 0.30 -0.25"/>
    <parent link="floor_link_1"/>
    <child link="floor_A1_utility_plate"/>
  </joint>
  <joint name="floor_A3_plate_box" type="fixed">
    <origin rpy="0 0 1.57079632679" xyz="-0.28 0.1 0.18"/>
    <parent link="floor_link_3"/>
    <child link="floor_A3_box"/>
  </joint>
  <joint name="gantry_A3_plate_box" type="fixed">
    <origin rpy="0 0 1.57079632679" xyz="-0.28 0.1 0.18"/>
    <parent link="gantry_link_3"/>
    <child link="gantry_A3_box"/>
  </joint>
</robot>

